Workbook

Sheet Rolling Forecast
B2: 12- Months Rolling Forecast With Analysis
A4: # | B4: Q1 Actuals (Refrence)
B5: Line Item | C5: 46023 | D5: Fed 26 | E5: 46082 | F5: Q1 Total
B6: =[1]Sheet1!B23 -> Revenue | C6: =Assumptions!C7 -> 280000 | D6: =Assumptions!D7 -> 295000 | E6: =Assumptions!E7 -> 310000 | F6: =Assumptions!F7 -> 885000
B7: =[1]Sheet1!B24 -> Gross Margin % | C7: =[1]Sheet1!C11 -> 0.7 | D7: =[1]Sheet1!D11 -> 0.7 | E7: =[1]Sheet1!E11 -> 0.7 | F7: =[1]Sheet1!F11 -> 0.7
B8: =[1]Sheet1!B25 -> EBITDA | C8: =[1]Sheet1!C16 -> -24000 | D8: =[1]Sheet1!D16 -> -18500 | E8: =[1]Sheet1!E16 -> -13000 | F8: =[1]Sheet1!F16 -> -55500
B11: Rolling Forecast Apr 2026 - Mar 2027
B12: Line Item | C12: 46113 | D12: 46143 | E12: 46174 | F12: 46204 | G12: 46235 | H12: 46266 | I12: 46296 | J12: 46327 | K12: 46357 | L12: 46388 | M12: 46419 | N12: 46447 | O12: 12M Total
B14: Revenue | C14: =E6*(1+Assumptions!$C$30) -> 322400 | D14: =C14*(1+Assumptions!$C$30) -> 335296 | E14: =D14*(1+Assumptions!$C$30) -> 348707.84 | F14: =E14*(1+Assumptions!$C$30) -> 362656.15 | G14: =F14*(1+Assumptions!$C$30) -> 377162.4 | H14: =G14*(1+Assumptions!$C$30) -> 392248.9 | I14: =H14*(1+Assumptions!$C$30) -> 407938.85 | J14: =I14*(1+Assumptions!$C$30) -> 424256.41 | K14: =J14*(1+Assumptions!$C$30) -> 441226.66 | L14: =K14*(1+Assumptions!$C$31) -> 463287.99 | M14: =L14*(1+Assumptions!$C$31) -> 486452.39 | N14: =M14*(1+Assumptions!$C$31) -> 510775.01 | O14: =SUM(C14:N14) -> 4872408.6
B15: Cost of Goods Sold | C15: =C14*(1-Assumptions!$C$32) -> 96720 | D15: =D14*(1-Assumptions!$C$32) -> 100588.8 | E15: =E14*(1-Assumptions!$C$32) -> 104612.35 | F15: =F14*(1-Assumptions!$C$32) -> 108796.85 | G15: =G14*(1-Assumptions!$C$32) -> 113148.72 | H15: =H14*(1-Assumptions!$C$32) -> 117674.67 | I15: =I14*(1-Assumptions!$C$32) -> 122381.66 | J15: =J14*(1-Assumptions!$C$32) -> 127276.92 | ... N15: =N14*(1-Assumptions!$C$32) -> 153232.5 | O15: =SUM(C15:N15) -> 1461722.6
B16: Gross Profit | C16: =C14-C15 -> 225680 | D16: =D14-D15 -> 234707.2 | E16: =E14-E15 -> 244095.49 | F16: =F14-F15 -> 253859.31 | G16: =G14-G15 -> 264013.68 | H16: =H14-H15 -> 274574.23 | I16: =I14-I15 -> 285557.2 | J16: =J14-J15 -> 296979.48 | ... N16: =N14-N15 -> 357542.51 | O16: =SUM(C16:N16) -> 3410686
B17: Gross Margin % | C17: =C16/C14 -> 0.7 | D17: =D16/D14 -> 0.7 | E17: =E16/E14 -> 0.7 | F17: =F16/F14 -> 0.7 | G17: =G16/G14 -> 0.7 | H17: =H16/H14 -> 0.7 | I17: =I16/I14 -> 0.7 | J17: =J16/J14 -> 0.7 | ... O17: =O16/O14 -> 0.7
B18: Operating Expenses:
B19: Sales & Marketing | C19: =C14*Assumptions!$C$33 -> 106392 | D19: =D14*Assumptions!$C$33 -> 110647.68 | E19: =E14*Assumptions!$C$33 -> 115073.59 | F19: =F14*Assumptions!$C$33 -> 119676.53 | G19: =G14*Assumptions!$C$33 -> 124463.59 | H19: =H14*Assumptions!$C$33 -> 129442.14 | I19: =I14*Assumptions!$C$33 -> 134619.82 | J19: =J14*Assumptions!$C$33 -> 140004.61 | ... N19: =N14*Assumptions!$C$33 -> 168555.75 | O19: =SUM(C19:N19) -> 1607894.8
B20: Research & Development | C20: =Assumptions!$C$34 -> 90000 | D20: =Assumptions!$C$34 -> 90000 | E20: =Assumptions!$C$34 -> 90000 | F20: =Assumptions!$C$34 -> 90000 | G20: =Assumptions!$C$34 -> 90000 | H20: =Assumptions!$C$34 -> 90000 | I20: =Assumptions!$C$34 -> 90000 | J20: =Assumptions!$C$34 -> 90000 | ... N20: =Assumptions!$C$34 -> 90000 | O20: =SUM(C20:N20) -> 1080000
B21: General & Administrative | C21: =Assumptions!$C$35 -> 40000 | D21: =Assumptions!$C$35 -> 40000 | E21: =Assumptions!$C$35 -> 40000 | F21: =Assumptions!$C$35 -> 40000 | G21: =Assumptions!$C$35 -> 40000 | H21: =Assumptions!$C$35 -> 40000 | I21: =Assumptions!$C$35 -> 40000 | J21: =Assumptions!$C$35 -> 40000 | ... N21: =Assumptions!$C$35 -> 40000 | O21: =SUM(C21:N21) -> 480000
B22: Total Operating Expenses | C22: =SUM(C19:C21) -> 236392 | D22: =SUM(D19:D21) -> 240647.68 | E22: =SUM(E19:E21) -> 245073.59 | F22: =SUM(F19:F21) -> 249676.53 | G22: =SUM(G19:G21) -> 254463.59 | H22: =SUM(H19:H21) -> 259442.14 | I22: =SUM(I19:I21) -> 264619.82 | J22: =SUM(J19:J21) -> 270004.61 | ... N22: =SUM(N19:N21) -> 298555.75 | O22: =SUM(C22:N22) -> 3167894.8
B23: EBITDA | C23: =C16-C22 -> -10712 | D23: =D16-D22 -> -5940.48 | E23: =E16-E22 -> -978.0992 | F23: =F16-F22 -> 4182.7768 | G23: =G16-G22 -> 9550.0879 | H23: =H16-H22 -> 15132.091 | I23: =I16-I22 -> 20937.375 | J23: =J16-J22 -> 26974.87 | ... O23: =O16-O22 -> 242791.19
B24: EBITDA Margin % | C24: =C23/C14 -> -0.033225806 | D24: =D23/D14 -> -0.017717122 | E24: =E23/E14 -> -0.0028049246 | F24: =F23/F14 -> 0.011533726 | G24: =G23/G14 -> 0.025320891 | H24: =H23/H14 -> 0.03857778 | I24: =I23/I14 -> 0.051324788 | J24: =J23/J14 -> 0.063581527 | ... O24: =O23/O14 -> 0.049829808
B27: Variance Analysis: Forecast vs Original Budget
B28: Metric | C28: Original FY2025 Budget | D28: Rolling 12M Forecast | E28: Variance ($) | F28: Variance (%)
B30: Revenue | C30: =Assumptions!E23 -> 4200000 | D30: =O14 -> 4872408.6 | E30: =D30-C30 -> 672408.61 | F30: =E30/C30 -> 0.16009729
B31: EBITDA | C31: =Assumptions!E25 -> 150000 | D31: =O23 -> 242791.19 | E31: =D31-C31 -> 92791.187 | F31: =E31/C31 -> 0.61860791
B32: EBITDA Margin % | C32: =C31/C30 -> 0.035714286 | D32: =D31/D30 -> 0.049829808 | E32: =D32-C32 -> 0.014115522 | F32: =E32 -> 0.014115522
A34: # | B34: Key Insights & Commentary
B36: 1. Revenue Trajectory:
B37: The rolling 12 month forecast (Apr 2026 - Mar 2027) Projects $4.87M in revenue, which in $672K (+16%) HIGHER than the orignal FY 2026 full -year budget of $4.2M. However, this comparison is not apples-to-apples: the budget covers Jan-Dec 2026 while the roliing forecast covers Apr-Mar 2027, which include three additional Q1 2027 months growing at 5% On a comparable basis (Apr-Dec 2026 only), the the forecast of 3.41M is modestly ahead of the implied budget remainder of $3.23M (+$97K, +3%) - reflecting slower-than-bugeted monthly gorwth (4% vs 5%) offset by a stronger-than-expected Q1 actuals base.
B39: 2. Profitability Timeline:
B40: EBITDA turns positive staring Jul-26 and improves steadily throught mar-27. EBITDA margin from -3.3% in Apr-26 to 11.16% by Mar-27. Rolling 12-month EBITDA total $242K, compared to budget EBITDA of $150K. This indicates the buisiness us expected to cross operating breakeven mid-year and achieve incerasing operating leverage as revenue scales.
B42: 3. Operating Levergae
B43: With 70% gross margin and operating expenses growing at a slower pace than revenue, operating leverage is clearly visible. Gross profit grows faster than operating expenses. EBITDA margin expands by ~15% points across.
B45: 4.Key Assumptions & Risk
B46: • Revenue growth rate (4% then 5%): Risk if market deteriorates further.
B47: • Gross margin maintenance at 70%: Dependent on pricing power and COGS control.
B48: • Sales & Marketing grows in line with revenue.
B49: • R&D and G&A largely fixed, supporting margin expansion.
A51: # | B51: Recommendations for Management
B53: 1. Protect revenue momentum: Sales execution and pipeline health should be top priorities.
B54: 2. Focus on gross margin: The 70% margin is a competitive advantage - protect it.
B55: 3. Maintain OpEx discipline: Allow fixed costs (R&D, G&A) to grow slower than revenue to preserve operating leverage.
...

Sheet Assumptions
B2: 12 months - Rolling Forecast
A4: # | B4: Q1 2026 Actual (Jan to Mar)
B5: Line Item | C5: 46023 | D5: Fed 26 | E5: 46082 | F5: Q1 Total
B7: Revenue | C7: 280000 | D7: 295000 | E7: 310000 | F7: =SUM(C7:E7) -> 885000
B8: Cost of Goods Sold | C8: 84000 | D8: 88500 | E8: 93000 | F8: =SUM(C8:E8) -> 265500
B9: Gross Profit | C9: 196000 | D9: 206500 | E9: 217000 | F9: =SUM(C9:E9) -> 619500
B10: Gross Margin | C10: =C9/C7 -> 0.7 | D10: =D9/D7 -> 0.7 | E10: =E9/E7 -> 0.7 | F10: =F9/F7 -> 0.7
B11: Operting Exp | C11: 220000 | D11: 225000 | E11: 230000 | F11: =SUM(C11:E11) -> 675000
B12: Sales & Marketing | C12: 98000 | D12: 100000 | E12: 105000 | F12: =SUM(C12:E12) -> 303000
B13: Research & Development | C13: 85000 | D13: 87000 | E13: 88000 | F13: =SUM(C13:E13) -> 260000
B14: General & Administrative | C14: 37000 | D14: 38000 | E14: 37000 | F14: =SUM(C14:E14) -> 112000
B15: EBITDA | C15: -24000 | D15: -18500 | E15: -13000 | F15: =SUM(C15:E15) -> -55500
B18: Original FY2025 Budget (for comparison)
B20: The budget assumed 5% monthly revenue growth and 68% gross margin. Q1 actuals show slower growth but better margin control.
B22: Budget line Item | C22: Q1 Budget | E22: Full Year
B23: Revenue | C23: 945000 | E23: 4200000
B24: Gross Margin % | C24: 0.68 | E24: 0.68
B25: EBITDA | C25: -15000 | E25: 150000
B27: Updated Assumptions (as of Mar 31, 2025):
B28: Assumptions | C28: Value | D28: Notes
B30: Revenue Growth Rate (Apr-Dec 2025) | C30: 0.04 | D30: 4% monthly (revised down from budget.)
B31: Revenue Growth Rate (Jan-Mar 2026) | C31: 0.05 | D31: 5% monthly (expecting acceleration)
B32: Gross Margin % | C32: 0.7 | D32: Maintain Q1 Performance
B33: S&M % of Revenue | C33: 0.33 | D33: (Cost control initiative)
B34: Research & Development | C34: 90000 | D34: (continued investment)
B35: General & Administrative | C35: 40000 | D35: (Fixed Cost)
